<mujoco model="ant">
  <compiler angle="radian" coordinate="local" inertiafromgeom="true"/>
  <option integrator="RK4" timestep="0.01"/>
    <size nconmax="500"/>
  <custom>
    <numeric data="0.0 0.0 0.55 1.0 0.0 0.0 0.0 0.0 1.0 0.0 -1.0 0.0 -1.0 0.0 1.0" name="init_qpos"/>
  </custom>
  <default>
    <joint armature="1" damping="1" limited="true"/>
    <geom conaffinity="0" condim="3" density="5.0" friction="1 0.5 0.5" margin="0.01" rgba="0.8 0.6 0.4 1"/>
  </default>
  <asset>
    <texture builtin="gradient" height="100" rgb1="1 1 1" rgb2="0 0 0" type="skybox" width="100"/>
    <texture builtin="flat" height="1278" mark="cross" markrgb="1 1 1" name="texgeom" random="0.01" rgb1="0.8 0.6 0.4" rgb2="0.8 0.6 0.4" type="cube" width="127"/>
    <texture builtin="checker" height="100" name="texplane" rgb1="0 0 0" rgb2="0.8 0.8 0.8" type="2d" width="100"/>
    <material name="MatPlane" reflectance="0.2" shininess="1" specular="1" texrepeat="0 0" texture="texplane"/>
    <material name="geom" texture="texgeom" texuniform="true"/>
  </asset>

  <worldbody>
    <light cutoff="100" diffuse="1 1 1" dir="-0 0 -1.3" directional="true" exponent="1" pos="0 0 1.3" specular=".1 .1 .1"/>
    <geom conaffinity="1" condim="3" material="MatPlane" name="floor" pos="0 0 0" rgba="0.8 0.9 0.8 1" size="10 10 1" type="plane"/>

    <body name="torso" pos="0 0 0.75">
      <camera name="track" mode="trackcom" pos="0 -3 0.3" xyaxes="1 0 0 0 0 1"/>
      <geom name="torso_geom" pos="0 0 0" size="0.25" mass="0.1" type="sphere"/>
      <joint armature="0" damping="0" limited="false" margin="0.01" name="root" pos="0 0 0" type="free"/>

      <body name="front_left_leg" pos="0 0 0">
        <geom fromto="0.0 0.0 0.0 0.2 0.2 0.0" name="aux_1_geom" size="0.08" type="capsule"/>
        <body name="aux_1" pos="0.2 0.2 0">
          <joint axis="0 0 1" name="hip_1" pos="0.0 0.0 0.0" range="-0.7 0.7" type="hinge"/>
          <geom fromto="0.0 0.0 0.0 0.2 0.2 0.0" name="left_leg_geom" size="0.08" type="capsule"/>
          <body pos="0.2 0.2 0">
            <joint axis="-1 1 0" name="ankle_1" pos="0.0 0.0 0.0" range="0.8 1.4" type="hinge"/>
            <geom fromto="0.0 0.0 0.0 0.4 0.4 0.0" name="left_ankle_geom" size="0.08" type="capsule"/>
          </body>
        </body>
      </body>

      <body name="front_right_leg" pos="0 0 0">
        <geom fromto="0.0 0.0 0.0 -0.2 0.2 0.0" name="aux_2_geom" size="0.08" type="capsule"/>
        <body name="aux_2" pos="-0.2 0.2 0">
          <joint axis="0 0 1" name="hip_2" pos="0.0 0.0 0.0" range="-0.7 0.7" type="hinge"/>
          <geom fromto="0.0 0.0 0.0 -0.2 0.2 0.0" name="right_leg_geom" size="0.08" type="capsule"/>
          <body pos="-0.2 0.2 0">
            <joint axis="1 1 0" name="ankle_2" pos="0.0 0.0 0.0" range="-1.4 -0.8" type="hinge"/>
            <geom fromto="0.0 0.0 0.0 -0.4 0.4 0.0" name="right_ankle_geom" size="0.08" type="capsule"/>
          </body>
        </body>
      </body>

      <body name="back_leg" pos="0 0 0">
        <geom fromto="0.0 0.0 0.0 -0.2 -0.2 0.0" name="aux_3_geom" size="0.08" type="capsule"/>
        <body name="aux_3" pos="-0.2 -0.2 0">
          <joint axis="0 0 1" name="hip_3" pos="0.0 0.0 0.0" range="-0.7 0.7" type="hinge"/>
          <geom fromto="0.0 0.0 0.0 -0.2 -0.2 0.0" name="back_leg_geom" size="0.08" type="capsule"/>
          <body pos="-0.2 -0.2 0">
            <joint axis="-1 1 0" name="ankle_3" pos="0.0 0.0 0.0" range="-1.4 -0.8" type="hinge"/>
            <geom fromto="0.0 0.0 0.0 -0.4 -0.4 0.0" name="third_ankle_geom" size="0.08" type="capsule"/>
          </body>
        </body>
      </body>

      <body name="right_back_leg" pos="0 0 0">
        <geom fromto="0.0 0.0 0.0 0.2 -0.2 0.0" name="aux_4_geom" size="0.08" type="capsule"/>
        <body name="aux_4" pos="0.2 -0.2 0">
          <joint axis="0 0 1" name="hip_4" pos="0.0 0.0 0.0" range="-0.7 0.7" type="hinge"/>
          <geom fromto="0.0 0.0 0.0 0.2 -0.2 0.0" name="rightback_leg_geom" size="0.08" type="capsule"/>
          <body pos="0.2 -0.2 0">
            <joint axis="1 1 0" name="ankle_4" pos="0.0 0.0 0.0" range="0.8 1.4" type="hinge"/>
            <geom fromto="0.0 0.0 0.0 0.4 -0.4 0.0" name="fourth_ankle_geom" size="0.08" type="capsule"/>
          </body>
        </body>
      </body>

      <body name="left_feeler" pos="0 0 0">
        <joint axis="0 0 1" name="lf1" pos="0.0 0.0 0.0" range="0.08 0.3" type="hinge"/>
        <geom fromto="0.2 0.0 0.0 0.6 0.0 0.0" name="lf1_geom" size="0.01" density="1" type="capsule" rgba="0 1 1 1"/>
        <body pos="0.6 0.0 0">
          <joint axis="0 1 0" name="lf2" pos="0.0 0.0 0.0" range="-0.65 0.3" type="hinge"/>
          <geom fromto="0.0 0.0 0.0 0.6 0.0 0.0" name="lf2_geom" size="0.01" density="1" type="capsule" rgba="0 1 1 1"/>
        </body>
      </body>

      <body name="right_feeler" pos="0 0 0">
        <joint axis="0 0 1" name="rf1" pos="0.0 0.0 0.0" range="-0.3 -0.08" type="hinge"/>
        <geom fromto="0.2 0.0 0.0 0.6 0.0 0.0" name="rf1_geom" size="0.01" density="1" type="capsule" rgba="0 1 1 1"/>
        <body pos="0.6 0.0 0">
          <joint axis="0 1 0" name="rf2" pos="0.0 0.0 0.0" range="-0.65 0.3" type="hinge"/>
          <geom fromto="0.0 0.0 0.0 0.6 0.0 0.0" name="rf2_geom" size="0.01" density="1" type="capsule" rgba="0 1 1 1"/>
        </body>
      </body>

    </body>


<!-- DEFINE CUBES AND GOAL HERE -->
    <body> 
        <geom conaffinity='1' condim='3' name='cube0_geom' pos='-4.832253695942503 -7.314656356819413 0.6' size='0.519537037293966 0.3653354570198303 0.6' rgba='1 1 1 1' mass='70' type='box'/>
     </body> 
    <body> 
        <geom conaffinity='1' condim='3' name='cube1_geom' pos='-5.587354518068869 1.0631784831678126 0.6' size='0.5130576222052854 0.5447233683413045 0.6' rgba='1 1 1 1' mass='70' type='box'/>
     </body> 
    <body> 
        <geom conaffinity='1' condim='3' name='cube2_geom' pos='-5.294077151912472 6.860204869221224 0.6' size='0.500025428646683 0.5918900894892288 0.6' rgba='1 1 1 1' mass='70' type='box'/>
     </body> 
    <body> 
        <geom conaffinity='1' condim='3' name='cube3_geom' pos='-0.9963923256200347 -5.09450505068112 0.6' size='0.38339900067761357 0.478820803253896 0.6' rgba='1 1 1 1' mass='70' type='box'/>
     </body> 
    <body> 
        <geom conaffinity='1' condim='3' name='cube4_geom' pos='1.2522466081328223 -0.3565860141569017 0.6' size='0.44179566871398873 0.5833678233553521 0.6' rgba='1 1 1 1' mass='70' type='box'/>
     </body> 
    <body> 
        <geom conaffinity='1' condim='3' name='cube5_geom' pos='-0.5573234948920368 6.702528980096819 0.6' size='0.5484202470724853 0.601561464257619 0.6' rgba='1 1 1 1' mass='70' type='box'/>
     </body> 
    <body> 
        <geom conaffinity='1' condim='3' name='cube6_geom' pos='5.272592313392343 -4.753497045800229 0.6' size='0.44811583335062777 0.4546346220749087 0.6' rgba='1 1 1 1' mass='70' type='box'/>
     </body> 
    <body> 
        <geom conaffinity='1' condim='3' name='cube7_geom' pos='6.86391062019079 -0.3578975847227439 0.6' size='0.5874099566483487 0.5359149332002706 0.6' rgba='1 1 1 1' mass='70' type='box'/>
     </body> 
    <body> 
        <geom conaffinity='1' condim='3' name='cube8_geom' pos='6.768821825877362 7.231421638883328 0.6' size='0.49960471139935286 0.4205868893300553 0.6' rgba='1 1 1 1' mass='70' type='box'/>
     </body> 
    <body> 
        <geom conaffinity='1' condim='3' name='goal_geom' pos='2.0533533367472883 2.2393105959646507 0.6' size='0.3' rgba='1 0 0 1' mass='1' type='sphere'/>
     </body> 



  </worldbody>

  <actuator>
    <position joint="hip_4" kp="20"/>
    <position joint="ankle_4" kp="20"/>
    <position joint="hip_1" kp="20"/>
    <position joint="ankle_1" kp="20"/>
    <position joint="hip_2" kp="20"/>
    <position joint="ankle_2" kp="20"/>
    <position joint="hip_3" kp="20"/>
    <position joint="ankle_3" kp="20"/>
    <motor ctrllimited="true" ctrlrange="-1.0 1.0" joint="lf1" gear="20"/>
    <motor ctrllimited="true" ctrlrange="-1.0 1.0" joint="lf2" gear="20"/>
    <motor ctrllimited="true" ctrlrange="-1.0 1.0" joint="rf1" gear="20"/>
    <motor ctrllimited="true" ctrlrange="-1.0 1.0" joint="rf2" gear="20"/>
  </actuator>
</mujoco>
